Workbook

Sheet Auto Menu
A1: CTC COMMISSARY MENU
A3: CLOTHING, SHOES, & UNDERWEAR
A4: THERMAL TOPS | F4: THERMAL BOTTOMS | K4: THERMAL SETS
B5: 1021 | C5: =INDEX('Master List Import'!$A$2:$P$700, MATCH('Auto Menu'!$B5, 'Master List Import'!$M$2:$M$700), 14) -> Thermal Top (Sm) | D5: =INDEX('Master List Import'!$A$2:$P$700, MATCH('Auto Menu'!$B5, 'Master List Import'!$M$2:$M$700), 16) -> 8.7 | G5: 1041 | H5: =INDEX('Master List Import'!$A$2:$P$700, MATCH('Auto Menu'!$G5, 'Master List Import'!$M$2:$M$700), 14) -> Thermal Bottom (Sm) | I5: =INDEX('Master List Import'!$A$2:$P$700, MATCH('Auto Menu'!$G5, 'Master List Import'!$M$2:$M$700), 16) -> 8.7 | L5: 1001 | M5: =INDEX('Master List Import'!$A$2:$P$700, MATCH('Auto Menu'!$L5, 'Master List Import'!$M$2:$M$700), 14) -> Thermal Set (Sm) | N5: =INDEX('Master List Import'!$A$2:$P$700, MATCH('Auto Menu'!$L5, 'Master List Import'!$M$2:$M$700), 16) -> 17.4
B6: 1022 | C6: =INDEX('Master List Import'!$A$2:$P$700, MATCH('Auto Menu'!$B6, 'Master List Import'!$M$2:$M$700), 14) -> Thermal Top (Md) | D6: =INDEX('Master List Import'!$A$2:$P$700, MATCH('Auto Menu'!$B6, 'Master List Import'!$M$2:$M$700), 16) -> 8.7 | G6: 1042 | H6: =INDEX('Master List Import'!$A$2:$P$700, MATCH('Auto Menu'!$G6, 'Master List Import'!$M$2:$M$700), 14) -> Thermal Bottom (Md) | I6: =INDEX('Master List Import'!$A$2:$P$700, MATCH('Auto Menu'!$G6, 'Master List Import'!$M$2:$M$700), 16) -> 8.7 | L6: 1002 | M6: =INDEX('Master List Import'!$A$2:$P$700, MATCH('Auto Menu'!$L6, 'Master List Import'!$M$2:$M$700), 14) -> Thermal Set (Md) | N6: =INDEX('Master List Import'!$A$2:$P$700, MATCH('Auto Menu'!$L6, 'Master List Import'!$M$2:$M$700), 16) -> 17.4
B7: 1023 | C7: =INDEX('Master List Import'!$A$2:$P$700, MATCH('Auto Menu'!$B7, 'Master List Import'!$M$2:$M$700), 14) -> Thermal Top (Lg) | D7: =INDEX('Master List Import'!$A$2:$P$700, MATCH('Auto Menu'!$B7, 'Master List Import'!$M$2:$M$700), 16) -> 8.7 | G7: 1043 | H7: =INDEX('Master List Import'!$A$2:$P$700, MATCH('Auto Menu'!$G7, 'Master List Import'!$M$2:$M$700), 14) -> Thermal Bottom (Lg) | I7: =INDEX('Master List Import'!$A$2:$P$700, MATCH('Auto Menu'!$G7, 'Master List Import'!$M$2:$M$700), 16) -> 8.7 | L7: 1003 | M7: =INDEX('Master List Import'!$A$2:$P$700, MATCH('Auto Menu'!$L7, 'Master List Import'!$M$2:$M$700), 14) -> Thermal Set (Lg) | N7: =INDEX('Master List Import'!$A$2:$P$700, MATCH('Auto Menu'!$L7, 'Master List Import'!$M$2:$M$700), 16) -> 17.4
B8: 1024 | C8: =INDEX('Master List Import'!$A$2:$P$700, MATCH('Auto Menu'!$B8, 'Master List Import'!$M$2:$M$700), 14) -> Thermal Top (XL) | D8: =INDEX('Master List Import'!$A$2:$P$700, MATCH('Auto Menu'!$B8, 'Master List Import'!$M$2:$M$700), 16) -> 8.7 | G8: 1044 | H8: =INDEX('Master List Import'!$A$2:$P$700, MATCH('Auto Menu'!$G8, 'Master List Import'!$M$2:$M$700), 14) -> Thermal Bottom (XL) | I8: =INDEX('Master List Import'!$A$2:$P$700, MATCH('Auto Menu'!$G8, 'Master List Import'!$M$2:$M$700), 16) -> 8.7 | L8: 1004 | M8: =INDEX('Master List Import'!$A$2:$P$700, MATCH('Auto Menu'!$L8, 'Master List Import'!$M$2:$M$700), 14) -> Thermal Set (XL) | N8: =INDEX('Master List Import'!$A$2:$P$700, MATCH('Auto Menu'!$L8, 'Master List Import'!$M$2:$M$700), 16) -> 17.4
B9: 1025 | C9: =INDEX('Master List Import'!$A$2:$P$700, MATCH('Auto Menu'!$B9, 'Master List Import'!$M$2:$M$700), 14) -> Thermal Top (2X) | D9: =INDEX('Master List Import'!$A$2:$P$700, MATCH('Auto Menu'!$B9, 'Master List Import'!$M$2:$M$700), 16) -> 10.2 | G9: 1045 | H9: =INDEX('Master List Import'!$A$2:$P$700, MATCH('Auto Menu'!$G9, 'Master List Import'!$M$2:$M$700), 14) -> Thermal Bottom (2X) | I9: =INDEX('Master List Import'!$A$2:$P$700, MATCH('Auto Menu'!$G9, 'Master List Import'!$M$2:$M$700), 16) -> 10.2 | L9: 1005 | M9: =INDEX('Master List Import'!$A$2:$P$700, MATCH('Auto Menu'!$L9, 'Master List Import'!$M$2:$M$700), 14) -> Thermal Set (2X) | N9: =INDEX('Master List Import'!$A$2:$P$700, MATCH('Auto Menu'!$L9, 'Master List Import'!$M$2:$M$700), 16) -> 20.4
B10: 1026 | C10: =INDEX('Master List Import'!$A$2:$P$700, MATCH('Auto Menu'!$B10, 'Master List Import'!$M$2:$M$700), 14) -> Thermal Top (3X) | D10: =INDEX('Master List Import'!$A$2:$P$700, MATCH('Auto Menu'!$B10, 'Master List Import'!$M$2:$M$700), 16) -> 10.9 | G10: 1046 | H10: =INDEX('Master List Import'!$A$2:$P$700, MATCH('Auto Menu'!$G10, 'Master List Import'!$M$2:$M$700), 14) -> Thermal Bottom (3X) | I10: =INDEX('Master List Import'!$A$2:$P$700, MATCH('Auto Menu'!$G10, 'Master List Import'!$M$2:$M$700), 16) -> 10.9 | L10: 1006 | M10: =INDEX('Master List Import'!$A$2:$P$700, MATCH('Auto Menu'!$L10, 'Master List Import'!$M$2:$M$700), 14) -> Thermal Set (3X) | N10: =INDEX('Master List Import'!$A$2:$P$700, MATCH('Auto Menu'!$L10, 'Master List Import'!$M$2:$M$700), 16) -> 21.8
B11: 1027 | C11: =INDEX('Master List Import'!$A$2:$P$700, MATCH('Auto Menu'!$B11, 'Master List Import'!$M$2:$M$700), 14) -> Thermal Top (4X) | D11: =INDEX('Master List Import'!$A$2:$P$700, MATCH('Auto Menu'!$B11, 'Master List Import'!$M$2:$M$700), 16) -> 11.6 | G11: 1047 | H11: =INDEX('Master List Import'!$A$2:$P$700, MATCH('Auto Menu'!$G11, 'Master List Import'!$M$2:$M$700), 14) -> Thermal Bottom (4X) | I11: =INDEX('Master List Import'!$A$2:$P$700, MATCH('Auto Menu'!$G11, 'Master List Import'!$M$2:$M$700), 16) -> 11.6 | L11: 1007 | M11: =INDEX('Master List Import'!$A$2:$P$700, MATCH('Auto Menu'!$L11, 'Master List Import'!$M$2:$M$700), 14) -> Thermal Set (4X) | N11: =INDEX('Master List Import'!$A$2:$P$700, MATCH('Auto Menu'!$L11, 'Master List Import'!$M$2:$M$700), 16) -> 23.2
B12: 1028 | C12: =INDEX('Master List Import'!$A$2:$P$700, MATCH('Auto Menu'!$B12, 'Master List Import'!$M$2:$M$700), 14) -> Thermal Top (5X) | D12: =INDEX('Master List Import'!$A$2:$P$700, MATCH('Auto Menu'!$B12, 'Master List Import'!$M$2:$M$700), 16) -> 12.6 | G12: 1048 | H12: =INDEX('Master List Import'!$A$2:$P$700, MATCH('Auto Menu'!$G12, 'Master List Import'!$M$2:$M$700), 14) -> Thermal Bottom (5X) | I12: =INDEX('Master List Import'!$A$2:$P$700, MATCH('Auto Menu'!$G12, 'Master List Import'!$M$2:$M$700), 16) -> 12.6 | L12: 1008 | M12: =INDEX('Master List Import'!$A$2:$P$700, MATCH('Auto Menu'!$L12, 'Master List Import'!$M$2:$M$700), 14) -> Thermal Set (5X) | N12: =INDEX('Master List Import'!$A$2:$P$700, MATCH('Auto Menu'!$L12, 'Master List Import'!$M$2:$M$700), 16) -> 25.2
A14: SWEATSHIRTS | F14: SWEATPANTS | K14: T-SHIRTS
B15: 1061 | C15: =INDEX('Master List Import'!$A$2:$P$700, MATCH('Auto Menu'!$B15, 'Master List Import'!$M$2:$M$700), 14) -> Grey Sweatshirt (Md) | D15: =INDEX('Master List Import'!$A$2:$P$700, MATCH('Auto Menu'!$B15, 'Master List Import'!$M$2:$M$700), 16) -> 21 | G15: 1071 | H15: =INDEX('Master List Import'!$A$2:$P$700, MATCH('Auto Menu'!$G15, 'Master List Import'!$M$2:$M$700), 14) -> Grey Sweatpants (Md) | I15: =INDEX('Master List Import'!$A$2:$P$700, MATCH('Auto Menu'!$G15, 'Master List Import'!$M$2:$M$700), 16) -> 25 | L15: 1201 | M15: =INDEX('Master List Import'!$A$2:$P$700, MATCH('Auto Menu'!$L15, 'Master List Import'!$M$2:$M$700), 14) -> White T-Shirt (Sm) | N15: =INDEX('Master List Import'!$A$2:$P$700, MATCH('Auto Menu'!$L15, 'Master List Import'!$M$2:$M$700), 16) -> 5.05
B16: 1062 | C16: =INDEX('Master List Import'!$A$2:$P$700, MATCH('Auto Menu'!$B16, 'Master List Import'!$M$2:$M$700), 14) -> Grey Sweatshirt (Lg) | D16: =INDEX('Master List Import'!$A$2:$P$700, MATCH('Auto Menu'!$B16, 'Master List Import'!$M$2:$M$700), 16) -> 21 | G16: 1072 | H16: =INDEX('Master List Import'!$A$2:$P$700, MATCH('Auto Menu'!$G16, 'Master List Import'!$M$2:$M$700), 14) -> Grey Sweatpants (Lg) | I16: =INDEX('Master List Import'!$A$2:$P$700, MATCH('Auto Menu'!$G16, 'Master List Import'!$M$2:$M$700), 16) -> 25 | L16: 1202 | M16: =INDEX('Master List Import'!$A$2:$P$700, MATCH('Auto Menu'!$L16, 'Master List Import'!$M$2:$M$700), 14) -> White T-Shirt (Md) | N16: =INDEX('Master List Import'!$A$2:$P$700, MATCH('Auto Menu'!$L16, 'Master List Import'!$M$2:$M$700), 16) -> 5.05
B17: 1063 | C17: =INDEX('Master List Import'!$A$2:$P$700, MATCH('Auto Menu'!$B17, 'Master List Import'!$M$2:$M$700), 14) -> Grey Sweatshirt (XL) | D17: =INDEX('Master List Import'!$A$2:$P$700, MATCH('Auto Menu'!$B17, 'Master List Import'!$M$2:$M$700), 16) -> 21 | G17: 1073 | H17: =INDEX('Master List Import'!$A$2:$P$700, MATCH('Auto Menu'!$G17, 'Master List Import'!$M$2:$M$700), 14) -> Grey Sweatpants (XL) | I17: =INDEX('Master List Import'!$A$2:$P$700, MATCH('Auto Menu'!$G17, 'Master List Import'!$M$2:$M$700), 16) -> 25 | L17: 1203 | M17: =INDEX('Master List Import'!$A$2:$P$700, MATCH('Auto Menu'!$L17, 'Master List Import'!$M$2:$M$700), 14) -> White T-Shirt (Lg) | N17: =INDEX('Master List Import'!$A$2:$P$700, MATCH('Auto Menu'!$L17, 'Master List Import'!$M$2:$M$700), 16) -> 5.05
B18: 1064 | C18: =INDEX('Master List Import'!$A$2:$P$700, MATCH('Auto Menu'!$B18, 'Master List Import'!$M$2:$M$700), 14) -> Grey Sweatshirt (2X) | D18: =INDEX('Master List Import'!$A$2:$P$700, MATCH('Auto Menu'!$B18, 'Master List Import'!$M$2:$M$700), 16) -> 24 | G18: 1074 | H18: =INDEX('Master List Import'!$A$2:$P$700, MATCH('Auto Menu'!$G18, 'Master List Import'!$M$2:$M$700), 14) -> Grey Sweatpants (2X) | I18: =INDEX('Master List Import'!$A$2:$P$700, MATCH('Auto Menu'!$G18, 'Master List Import'!$M$2:$M$700), 16) -> 28 | L18: 1204 | M18: =INDEX('Master List Import'!$A$2:$P$700, MATCH('Auto Menu'!$L18, 'Master List Import'!$M$2:$M$700), 14) -> White T-Shirt (XL) | N18: =INDEX('Master List Import'!$A$2:$P$700, MATCH('Auto Menu'!$L18, 'Master List Import'!$M$2:$M$700), 16) -> 5.05
B19: 1065 | C19: =INDEX('Master List Import'!$A$2:$P$700, MATCH('Auto Menu'!$B19, 'Master List Import'!$M$2:$M$700), 14) -> Grey Sweatshirt (3X) | D19: =INDEX('Master List Import'!$A$2:$P$700, MATCH('Auto Menu'!$B19, 'Master List Import'!$M$2:$M$700), 16) -> 28 | G19: 1075 | H19: =INDEX('Master List Import'!$A$2:$P$700, MATCH('Auto Menu'!$G19, 'Master List Import'!$M$2:$M$700), 14) -> Grey Sweatpants (3X) | I19: =INDEX('Master List Import'!$A$2:$P$700, MATCH('Auto Menu'!$G19, 'Master List Import'!$M$2:$M$700), 16) -> 32 | L19: 1205 | M19: =INDEX('Master List Import'!$A$2:$P$700, MATCH('Auto Menu'!$L19, 'Master List Import'!$M$2:$M$700), 14) -> White T-Shirt (2X) | N19: =INDEX('Master List Import'!$A$2:$P$700, MATCH('Auto Menu'!$L19, 'Master List Import'!$M$2:$M$700), 16) -> 7.25
B20: 1066 | C20: =INDEX('Master List Import'!$A$2:$P$700, MATCH('Auto Menu'!$B20, 'Master List Import'!$M$2:$M$700), 14) -> Grey Sweatshirt (4X) | D20: =INDEX('Master List Import'!$A$2:$P$700, MATCH('Auto Menu'!$B20, 'Master List Import'!$M$2:$M$700), 16) -> 32 | G20: 1076 | H20: =INDEX('Master List Import'!$A$2:$P$700, MATCH('Auto Menu'!$G20, 'Master List Import'!$M$2:$M$700), 14) -> Grey Sweatpants (4X) | I20: =INDEX('Master List Import'!$A$2:$P$700, MATCH('Auto Menu'!$G20, 'Master List Import'!$M$2:$M$700), 16) -> 34.5 | L20: 1206 | M20: =INDEX('Master List Import'!$A$2:$P$700, MATCH('Auto Menu'!$L20, 'Master List Import'!$M$2:$M$700), 14) -> White T-Shirt (3X) | N20: =INDEX('Master List Import'!$A$2:$P$700, MATCH('Auto Menu'!$L20, 'Master List Import'!$M$2:$M$700), 16) -> 7.25
B21: 1067 | C21: =INDEX('Master List Import'!$A$2:$P$700, MATCH('Auto Menu'!$B21, 'Master List Import'!$M$2:$M$700), 14) -> Grey Sweatshirt (5XL) | D21: =INDEX('Master List Import'!$A$2:$P$700, MATCH('Auto Menu'!$B21, 'Master List Import'!$M$2:$M$700), 16) -> 33.5 | G21: 1077 | H21: =INDEX('Master List Import'!$A$2:$P$700, MATCH('Auto Menu'!$G21, 'Master List Import'!$M$2:$M$700), 14) -> Grey Sweatpants (5XL) | I21: =INDEX('Master List Import'!$A$2:$P$700, MATCH('Auto Menu'!$G21, 'Master List Import'!$M$2:$M$700), 16) -> 35.5 | L21: 1207 | M21: =INDEX('Master List Import'!$A$2:$P$700, MATCH('Auto Menu'!$L21, 'Master List Import'!$M$2:$M$700), 14) -> White T-Shirt (4X) | N21: =INDEX('Master List Import'!$A$2:$P$700, MATCH('Auto Menu'!$L21, 'Master List Import'!$M$2:$M$700), 16) -> 8.25
B22: 1068 | C22: =INDEX('Master List Import'!$A$2:$P$700, MATCH('Auto Menu'!$B22, 'Master List Import'!$M$2:$M$700), 14) -> Grey Sweatshirt (6XL) | D22: =INDEX('Master List Import'!$A$2:$P$700, MATCH('Auto Menu'!$B22, 'Master List Import'!$M$2:$M$700), 16) -> 36.5 | G22: 1078 | H22: =INDEX('Master List Import'!$A$2:$P$700, MATCH('Auto Menu'!$G22, 'Master List Import'!$M$2:$M$700), 14) -> Grey Sweatpants (6XL) | I22: =INDEX('Master List Import'!$A$2:$P$700, MATCH('Auto Menu'!$G22, 'Master List Import'!$M$2:$M$700), 16) -> 38.5 | L22: 1208 | M22: =INDEX('Master List Import'!$A$2:$P$700, MATCH('Auto Menu'!$L22, 'Master List Import'!$M$2:$M$700), 14) -> White T-Shirt (5X) | N22: =INDEX('Master List Import'!$A$2:$P$700, MATCH('Auto Menu'!$L22, 'Master List Import'!$M$2:$M$700), 16) -> 10.15
L23: 1209 | M23: =INDEX('Master List Import'!$A$2:$P$700, MATCH('Auto Menu'!$L23, 'Master List Import'!$M$2:$M$700), 14) -> White T-Shirt (6X) | N23: =INDEX('Master List Import'!$A$2:$P$700, MATCH('Auto Menu'!$L23, 'Master List Import'!$M$2:$M$700), 16) -> 12.15
A25: SOCKS | F25: MEN'S UNDERWEAR | K25: LINENS, LAUNDRY
B26: 1111 | C26: =INDEX('Master List Import'!$A$2:$P$700, MATCH('Auto Menu'!$B26, 'Master List Import'!$M$2:$M$700), 14) -> White Crew Socks | D26: =INDEX('Master List Import'!$A$2:$P$700, MATCH('Auto Menu'!$B26, 'Master List Import'!$M$2:$M$700), 16) -> 2.1 | G26: 1301 | H26: =INDEX('Master List Import'!$A$2:$P$700, MATCH('Auto Menu'!$G26, 'Master List Import'!$M$2:$M$700), 14) -> White Boxers (Sm) | I26: =INDEX('Master List Import'!$A$2:$P$700, MATCH('Auto Menu'!$G26, 'Master List Import'!$M$2:$M$700), 16) -> 4.3 | L26: 1900 | M26: =INDEX('Master List Import'!$A$2:$P$700, MATCH('Auto Menu'!$L26, 'Master List Import'!$M$2:$M$700), 14) -> White Bath Towel (Sm) | N26: =INDEX('Master List Import'!$A$2:$P$700, MATCH('Auto Menu'!$L26, 'Master List Import'!$M$2:$M$700), 16) -> 5.6
G27: 1302 | H27: =INDEX('Master List Import'!$A$2:$P$700, MATCH('Auto Menu'!$G27, 'Master List Import'!$M$2:$M$700), 14) -> White Boxers (Md) | I27: =INDEX('Master List Import'!$A$2:$P$700, MATCH('Auto Menu'!$G27, 'Master List Import'!$M$2:$M$700), 16) -> 4.3 | L27: 1901 | M27: =INDEX('Master List Import'!$A$2:$P$700, MATCH('Auto Menu'!$L27, 'Master List Import'!$M$2:$M$700), 14) -> White Bath Towel (Md) | N27: =INDEX('Master List Import'!$A$2:$P$700, MATCH('Auto Menu'!$L27, 'Master List Import'!$M$2:$M$700), 16) -> 5.8
A28: SHOES | G28: 1303 | H28: =INDEX('Master List Import'!$A$2:$P$700, MATCH('Auto Menu'!$G28, 'Master List Import'!$M$2:$M$700), 14) -> White Boxers (Lg) | I28: =INDEX('Master List Import'!$A$2:$P$700, MATCH('Auto Menu'!$G28, 'Master List Import'!$M$2:$M$700), 16) -> 4.3 | L28: 1910 | M28: =INDEX('Master List Import'!$A$2:$P$700, MATCH('Auto Menu'!$L28, 'Master List Import'!$M$2:$M$700), 14) -> Tan Bath Towel (Lg) | N28: =INDEX('Master List Import'!$A$2:$P$700, MATCH('Auto Menu'!$L28, 'Master List Import'!$M$2:$M$700), 16) -> 11
B29: 1602 | C29: =INDEX('Master List Import'!$A$2:$P$700, MATCH('Auto Menu'!$B29, 'Master List Import'!$M$2:$M$700), 14) -> Black Canvas Shoes (M07/L09) | D29: =INDEX('Master List Import'!$A$2:$P$700, MATCH('Auto Menu'!$B29, 'Master List Import'!$M$2:$M$700), 16) -> 15.55 | G29: 1304 | H29: =INDEX('Master List Import'!$A$2:$P$700, MATCH('Auto Menu'!$G29, 'Master List Import'!$M$2:$M$700), 14) -> White Boxers (XL) | I29: =INDEX('Master List Import'!$A$2:$P$700, MATCH('Auto Menu'!$G29, 'Master List Import'!$M$2:$M$700), 16) -> 4.3 | L29: 1920 | M29: =INDEX('Master List Import'!$A$2:$P$700, MATCH('Auto Menu'!$L29, 'Master List Import'!$M$2:$M$700), 14) -> Blue Bath Towel (Lg) | N29: =INDEX('Master List Import'!$A$2:$P$700, MATCH('Auto Menu'!$L29, 'Master List Import'!$M$2:$M$700), 16) -> 10.5
B30: 1603 | C30: =INDEX('Master List Import'!$A$2:$P$700, MATCH('Auto Menu'!$B30, 'Master List Import'!$M$2:$M$700), 14) -> Black Canvas Shoes (M08/L10) | D30: =INDEX('Master List Import'!$A$2:$P$700, MATCH('Auto Menu'!$B30, 'Master List Import'!$M$2:$M$700), 16) -> 15.55 | G30: 1305 | H30: =INDEX('Master List Import'!$A$2:$P$700, MATCH('Auto Menu'!$G30, 'Master List Import'!$M$2:$M$700), 14) -> White Boxers (2X) | I30: =INDEX('Master List Import'!$A$2:$P$700, MATCH('Auto Menu'!$G30, 'Master List Import'!$M$2:$M$700), 16) -> 4.8 | L30: 1800 | M30: =INDEX('Master List Import'!$A$2:$P$700, MATCH('Auto Menu'!$L30, 'Master List Import'!$M$2:$M$700), 14) -> White Washcloth | N30: =INDEX('Master List Import'!$A$2:$P$700, MATCH('Auto Menu'!$L30, 'Master List Import'!$M$2:$M$700), 16) -> 1
B31: 1604 | C31: =INDEX('Master List Import'!$A$2:$P$700, MATCH('Auto Menu'!$B31, 'Master List Import'!$M$2:$M$700), 14) -> Black Canvas Shoes (M09/L11) | D31: =INDEX('Master List Import'!$A$2:$P$700, MATCH('Auto Menu'!$B31, 'Master List Import'!$M$2:$M$700), 16) -> 15.55 | G31: 1306 | H31: =INDEX('Master List Import'!$A$2:$P$700, MATCH('Auto Menu'!$G31, 'Master List Import'!$M$2:$M$700), 14) -> White Boxers (3X) | I31: =INDEX('Master List Import'!$A$2:$P$700, MATCH('Auto Menu'!$G31, 'Master List Import'!$M$2:$M$700), 16) -> 5.8 | L31: 1810 | M31: =INDEX('Master List Import'!$A$2:$P$700, MATCH('Auto Menu'!$L31, 'Master List Import'!$M$2:$M$700), 14) -> Tan Washcloth | N31: =INDEX('Master List Import'!$A$2:$P$700, MATCH('Auto Menu'!$L31, 'Master List Import'!$M$2:$M$700), 16) -> 5
B32: 1605 | C32: =INDEX('Master List Import'!$A$2:$P$700, MATCH('Auto Menu'!$B32, 'Master List Import'!$M$2:$M$700), 14) -> Black Canvas Shoes (M10/L12) | D32: =INDEX('Master List Import'!$A$2:$P$700, MATCH('Auto Menu'!$B32, 'Master List Import'!$M$2:$M$700), 16) -> 15.55 | G32: 1307 | H32: =INDEX('Master List Import'!$A$2:$P$700, MATCH('Auto Menu'!$G32, 'Master List Import'!$M$2:$M$700), 14) -> White Boxers (4X) | I32: =INDEX('Master List Import'!$A$2:$P$700, MATCH('Auto Menu'!$G32, 'Master List Import'!$M$2:$M$700), 16) -> 6.05 | L32: 1820 | M32: =INDEX('Master List Import'!$A$2:$P$700, MATCH('Auto Menu'!$L32, 'Master List Import'!$M$2:$M$700), 14) -> Blue Washcloth | N32: =INDEX('Master List Import'!$A$2:$P$700, MATCH('Auto Menu'!$L32, 'Master List Import'!$M$2:$M$700), 16) -> 2.1
B33: 1606 | C33: =INDEX('Master List Import'!$A$2:$P$700, MATCH('Auto Menu'!$B33, 'Master List Import'!$M$2:$M$700), 14) -> Black Canvas Shoes (M11) | D33: =INDEX('Master List Import'!$A$2:$P$700, MATCH('Auto Menu'!$B33, 'Master List Import'!$M$2:$M$700), 16) -> 15.55 | G33: 1308 | H33: =INDEX('Master List Import'!$A$2:$P$700, MATCH('Auto Menu'!$G33, 'Master List Import'!$M$2:$M$700), 14) -> White Boxers (5X) | I33: =INDEX('Master List Import'!$A$2:$P$700, MATCH('Auto Menu'!$G33, 'Master List Import'!$M$2:$M$700), 16) -> 6.8 | L33: 2000 | M33: =INDEX('Master List Import'!$A$2:$P$700, MATCH('Auto Menu'!$L33, 'Master List Import'!$M$2:$M$700), 14) -> Mesh Laundry Bag | N33: =INDEX('Master List Import'!$A$2:$P$700, MATCH('Auto Menu'!$L33, 'Master List Import'!$M$2:$M$700), 16) -> 7.5
B34: 1607 | C34: =INDEX('Master List Import'!$A$2:$P$700, MATCH('Auto Menu'!$B34, 'Master List Import'!$M$2:$M$700), 14) -> Black Canvas Shoes (M12) | D34: =INDEX('Master List Import'!$A$2:$P$700, MATCH('Auto Menu'!$B34, 'Master List Import'!$M$2:$M$700), 16) -> 15.55 | G34: 1309 | H34: =INDEX('Master List Import'!$A$2:$P$700, MATCH('Auto Menu'!$G34, 'Master List Import'!$M$2:$M$700), 14) -> White Boxers (6X) | I34: =INDEX('Master List Import'!$A$2:$P$700, MATCH('Auto Menu'!$G34, 'Master List Import'!$M$2:$M$700), 16) -> 7.5
B35: 1608 | C35: =INDEX('Master List Import'!$A$2:$P$700, MATCH('Auto Menu'!$B35, 'Master List Import'!$M$2:$M$700), 14) -> Black Canvas Shoes (M13) | D35: =INDEX('Master List Import'!$A$2:$P$700, MATCH('Auto Menu'!$B35, 'Master List Import'!$M$2:$M$700), 16) -> 15.55
B36: 1609 | C36: =INDEX('Master List Import'!$A$2:$P$700, MATCH('Auto Menu'!$B36, 'Master List Import'!$M$2:$M$700), 14) -> Black Canvas Shoes (M14) | D36: =INDEX('Master List Import'!$A$2:$P$700, MATCH('Auto Menu'!$B36, 'Master List Import'!$M$2:$M$700), 16) -> 15.55
B37: 1610 | C37: =INDEX('Master List Import'!$A$2:$P$700, MATCH('Auto Menu'!$B37, 'Master List Import'!$M$2:$M$700), 14) -> Black Canvas Shoes (M15) | D37: =INDEX('Master List Import'!$A$2:$P$700, MATCH('Auto Menu'!$B37, 'Master List Import'!$M$2:$M$700), 16) -> 15.55 | F37: WOMEN'S UNDERWEAR
B38: 1703 | C38: =INDEX('Master List Import'!$A$2:$P$700, MATCH('Auto Menu'!$B38, 'Master List Import'!$M$2:$M$700), 14) -> Shower Sandals (08) | D38: =INDEX('Master List Import'!$A$2:$P$700, MATCH('Auto Menu'!$B38, 'Master List Import'!$M$2:$M$700), 16) -> 8 | G38: 1400 | H38: =INDEX('Master List Import'!$A$2:$P$700, MATCH('Auto Menu'!$G38, 'Master List Import'!$M$2:$M$700), 14) -> White Panties (Sz 05) | I38: =INDEX('Master List Import'!$A$2:$P$700, MATCH('Auto Menu'!$G38, 'Master List Import'!$M$2:$M$700), 16) -> 2.95
B39: 1705 | C39: =INDEX('Master List Import'!$A$2:$P$700, MATCH('Auto Menu'!$B39, 'Master List Import'!$M$2:$M$700), 14) -> Shower Sandals (10) | D39: =INDEX('Master List Import'!$A$2:$P$700, MATCH('Auto Menu'!$B39, 'Master List Import'!$M$2:$M$700), 16) -> 8 | G39: 1401 | H39: =INDEX('Master List Import'!$A$2:$P$700, MATCH('Auto Menu'!$G39, 'Master List Import'!$M$2:$M$700), 14) -> White Panties (Sz 06) | I39: =INDEX('Master List Import'!$A$2:$P$700, MATCH('Auto Menu'!$G39, 'Master List Import'!$M$2:$M$700), 16) -> 2.95
B40: 1707 | C40: =INDEX('Master List Import'!$A$2:$P$700, MATCH('Auto Menu'!$B40, 'Master List Import'!$M$2:$M$700), 14) -> Shower Sandals (12) | D40: =INDEX('Master List Import'!$A$2:$P$700, MATCH('Auto Menu'!$B40, 'Master List Import'!$M$2:$M$700), 16) -> 8 | G40: 1402 | H40: =INDEX('Master List Import'!$A$2:$P$700, MATCH('Auto Menu'!$G40, 'Master List Import'!$M$2:$M$700), 14) -> White Panties (Sz 07) | I40: =INDEX('Master List Import'!$A$2:$P$700, MATCH('Auto Menu'!$G40, 'Master List Import'!$M$2:$M$700), 16) -> 2.95
B41: 1708 | C41: =INDEX('Master List Import'!$A$2:$P$700, MATCH('Auto Menu'!$B41, 'Master List Import'!$M$2:$M$700), 14) -> Shower Sandals (14) | D41: =INDEX('Master List Import'!$A$2:$P$700, MATCH('Auto Menu'!$B41, 'Master List Import'!$M$2:$M$700), 16) -> 8 | G41: 1403 | H41: =INDEX('Master List Import'!$A$2:$P$700, MATCH('Auto Menu'!$G41, 'Master List Import'!$M$2:$M$700), 14) -> White Panties (Sz 08) | I41: =INDEX('Master List Import'!$A$2:$P$700, MATCH('Auto Menu'!$G41, 'Master List Import'!$M$2:$M$700), 16) -> 2.95
B42: 1710 | C42: =INDEX('Master List Import'!$A$2:$P$700, MATCH('Auto Menu'!$B42, 'Master List Import'!$M$2:$M$700), 14) -> Shower Sandals (17) | D42: =INDEX('Master List Import'!$A$2:$P$700, MATCH('Auto Menu'!$B42, 'Master List Import'!$M$2:$M$700), 16) -> 8 | G42: 1404 | H42: =INDEX('Master List Import'!$A$2:$P$700, MATCH('Auto Menu'!$G42, 'Master List Import'!$M$2:$M$700), 14) -> White Panties (Sz 09) | I42: =INDEX('Master List Import'!$A$2:$P$700, MATCH('Auto Menu'!$G42, 'Master List Import'!$M$2:$M$700), 16) -> 3.05
B43: 1622 | C43: =INDEX('Master List Import'!$A$2:$P$700, MATCH('Auto Menu'!$B43, 'Master List Import'!$M$2:$M$700), 14) -> Orange Canvas Shoes (M07/L09) | D43: =INDEX('Master List Import'!$A$2:$P$700, MATCH('Auto Menu'!$B43, 'Master List Import'!$M$2:$M$700), 16) -> 15.55 | G43: 1405 | H43: =INDEX('Master List Import'!$A$2:$P$700, MATCH('Auto Menu'!$G43, 'Master List Import'!$M$2:$M$700), 14) -> White Panties (Sz 10) | I43: =INDEX('Master List Import'!$A$2:$P$700, MATCH('Auto Menu'!$G43, 'Master List Import'!$M$2:$M$700), 16) -> 3.3
...

Sheet Master List Import
A1: Item ID | B1: ItemID | C1: Description | D1: Category | E1: Sales Type | F1: Gender | G1: Last Cost | H1: Vendor ID | I1: Vendor Item | J1: Min Qty | K1: Max Qty | L1: Case Qty | M1: Scan Code | N1: CustomerItemDescription | O1: Multiplier | P1: Stnd Price | Q1: Column17 | R1: Column18 | S1: Column19 | T1: Column20 | U1: Column21 | V1: Column22 | W1: Column23 | X1: Column24 | Y1: Column25 | Z1: Column26
A2: 1001 | B2: 1001 | C2: Thermal Set - Sm | D2: Clothing | E2: Clothing | F2: Both | G2: 4.96 | H2: REI | I2: 1001 | J2: 0 | K2: 0 | L2: 1 | M2: 1001 | N2: Thermal Set (Sm) | O2: 1 | P2: 17.4
A3: 1002 | B3: 1002 | C3: Thermal Set - Md | D3: Clothing | E3: Clothing | F3: Both | G3: 4.96 | H3: REI | I3: 1002 | J3: 0 | K3: 0 | L3: 1 | M3: 1002 | N3: Thermal Set (Md) | O3: 1 | P3: 17.4
A4: 1003 | B4: 1003 | C4: Thermal Set - Lg | D4: Clothing | E4: Clothing | F4: Both | G4: 4.96 | H4: REI | I4: 1003 | J4: 0 | K4: 0 | L4: 1 | M4: 1003 | N4: Thermal Set (Lg) | O4: 1 | P4: 17.4
A5: 1004 | B5: 1004 | C5: Thermal Set - XL | D5: Clothing | E5: Clothing | F5: Both | G5: 4.96 | H5: REI | I5: 1004 | J5: 0 | K5: 0 | L5: 1 | M5: 1004 | N5: Thermal Set (XL) | O5: 1 | P5: 17.4
A6: 1005 | B6: 1005 | C6: Thermal Set - 2X | D6: Clothing | E6: Clothing | F6: Both | G6: 5.84 | H6: REI | I6: 1005 | J6: 0 | K6: 0 | L6: 1 | M6: 1005 | N6: Thermal Set (2X) | O6: 1 | P6: 20.4
A7: 1006 | B7: 1006 | C7: Thermal Set - 3X | D7: Clothing | E7: Clothing | F7: Both | G7: 6.24 | H7: REI | I7: 1006 | J7: 0 | K7: 0 | L7: 1 | M7: 1006 | N7: Thermal Set (3X) | O7: 1 | P7: 21.8
A8: 1007 | B8: 1007 | C8: Thermal Set - 4X | D8: Clothing | E8: Clothing | F8: Both | G8: 6.64 | H8: REI | I8: 1007 | J8: 0 | K8: 0 | L8: 1 | M8: 1007 | N8: Thermal Set (4X) | O8: 1 | P8: 23.2
A9: 1008 | B9: 1008 | C9: Thermal Set - 5X | D9: Clothing | E9: Clothing | F9: Both | G9: 7.2 | H9: REI | I9: 1008 | J9: 0 | K9: 0 | L9: 1 | M9: 1008 | N9: Thermal Set (5X) | O9: 1 | P9: 25.2
A10: 1021 | B10: 1021 | C10: Thermal Top - Sm | D10: Clothing | E10: Clothing | F10: Both | G10: 2.48 | H10: REI | I10: 900701 | J10: 0 | K10: 0 | L10: 1 | M10: 1021 | N10: Thermal Top (Sm) | O10: 1 | P10: 8.7
A11: 1022 | B11: 1022 | C11: Thermal Top - Md | D11: Clothing | E11: Clothing | F11: Both | G11: 2.48 | H11: REI | I11: 900702 | J11: 0 | K11: 0 | L11: 1 | M11: 1022 | N11: Thermal Top (Md) | O11: 1 | P11: 8.7
A12: 1023 | B12: 1023 | C12: Thermal Top - Lg | D12: Clothing | E12: Clothing | F12: Both | G12: 2.48 | H12: REI | I12: 900703 | J12: 0 | K12: 0 | L12: 1 | M12: 1023 | N12: Thermal Top (Lg) | O12: 1 | P12: 8.7
A13: 1024 | B13: 1024 | C13: Thermal Top - XL | D13: Clothing | E13: Clothing | F13: Both | G13: 2.48 | H13: REI | I13: 900704 | J13: 0 | K13: 0 | L13: 1 | M13: 1024 | N13: Thermal Top (XL) | O13: 1 | P13: 8.7
... A519: 8900 | B519: 8900 | C519: Pop's Snack Shack Sugar Free Assorted Fruit Hard Candy | D519: Diabetic | E519: Diabetic | F519: Both | G519: 0.63 | H519: REI | I519: 057626 | J519: 0 | K519: 0 | L519: 1 | M519: 8900 | N519: Sugar Free Assorted Candy | O519: 1 | P519: 2.25
